01:01:16 PM:DEBUG [logger_base.py:14] Mensaje a nivel debug
01:01:16 PM:INFO [logger_base.py:15] Mensaje a nivel info
01:01:16 PM:WARNING [logger_base.py:16] Mensaje a nivel error
01:01:16 PM:CRITICAL [logger_base.py:17] Mensaje a nivel critical
03:09:07 PM:DEBUG [Persona.py:53] 
                Id persona: 1,
                Nombre: Juan,
                Apellido: Perez,
                Email: jperez@mail.com
            
                
03:10:20 PM:DEBUG [Persona.py:53] 
                Id persona: 1,
                Nombre: Juan,
                Apellido: Perez,
                Email: jperez@mail.com
            
                
03:10:32 PM:DEBUG [Persona.py:53] 
                Id persona: 1,
                Nombre: Juan,
                Apellido: Perez,
                Email: jperez@mail.com
            
                
03:10:56 PM:DEBUG [Persona.py:53] 
                Id persona: 1,
                Nombre: Juan,
                Apellido: Perez,
                Email: jperez@mail.com
            
                
03:10:56 PM:DEBUG [Persona.py:55] 
                Id persona: 2,
                Nombre: Jose,
                Apellido: Lopez,
                Email: jose@mail.com
            
                
03:13:27 PM:DEBUG [Persona.py:56] 
                Id persona: 1,
                Nombre: Juan,
                Apellido: Perez,
                Email: jperez@mail.com
            
                
03:13:27 PM:DEBUG [Persona.py:58] 
                Id persona: None,
                Nombre: Jose,
                Apellido: Lopez,
                Email: jose@mail.com
            
                
03:13:27 PM:DEBUG [Persona.py:60] 
                Id persona: 1,
                Nombre: None,
                Apellido: None,
                Email: None
            
                
03:39:48 PM:DEBUG [conexion.py:26] Conexión Exitosa: <connection object at 0x000001E29FFCD360; dsn: 'user=postgres password=xxx dbname=test_bd host=localhost port=5432', closed: 0>
03:40:06 PM:DEBUG [conexion.py:26] Conexión Exitosa: <connection object at 0x000001CCCB8CD360; dsn: 'user=postgres password=xxx dbname=test_bd host=localhost port=5432', closed: 0>
03:41:02 PM:DEBUG [conexion.py:26] Conexión Exitosa: <connection object at 0x000001E631ECD360; dsn: 'user=postgres password=xxx dbname=test_bd host=localhost port=5432', closed: 0>
03:41:02 PM:ERROR [conexion.py:42] Ocurrió un error que rompió todo: 'NoneType' object has no attribute 'cursor'
03:42:16 PM:DEBUG [conexion.py:26] Conexión Exitosa: <connection object at 0x000001D03C23D360; dsn: 'user=postgres password=xxx dbname=test_bd host=localhost port=5432', closed: 0>
03:42:16 PM:ERROR [conexion.py:42] Ocurrió un error que rompió todo: 'NoneType' object has no attribute 'cursor'
03:42:34 PM:DEBUG [conexion.py:26] Conexión Exitosa: <connection object at 0x000001CA1758D360; dsn: 'user=postgres password=xxx dbname=test_bd host=localhost port=5432', closed: 0>
03:42:34 PM:DEBUG [conexion.py:39] Se abrió correctamente el cursor, sos un genio loco: <cursor object at 0x000001CA17226180; closed: 0>
09:23:47 PM:DEBUG [cursor_del_pool.py:10] Inicio del metodo with y __enter__
09:23:47 PM:ERROR [conexion.py:29] Ocurrió un error de la gran flauta: connection to server at "localhost" (::1), port 3306 failed: received invalid response to SSL negotiation: J

09:24:53 PM:INFO [menu_app_usuario.py:20] Salimos de la aplicación, hasta pronto!
09:38:11 PM:DEBUG [cursor_del_pool.py:10] Inicio del metodo with y __enter__
09:38:11 PM:ERROR [conexion.py:29] Ocurrió un error de la gran flauta: connection to server at "localhost" (::1), port 3306 failed: received invalid response to SSL negotiation: J

09:39:58 PM:DEBUG [cursor_del_pool.py:10] Inicio del metodo with y __enter__
09:39:58 PM:ERROR [conexion.py:30] Ocurrió un error de la gran flauta: connection to server at "localhost" (::1), port 3306 failed: received invalid response to SSL negotiation: J

09:40:45 PM:DEBUG [cursor_del_pool.py:10] Inicio del metodo with y __enter__
09:40:45 PM:ERROR [conexion.py:30] Ocurrió un error de la gran flauta: connection to server at "127.0.0.1", port 3306 failed: received invalid response to SSL negotiation: J

09:41:36 PM:DEBUG [cursor_del_pool.py:10] Inicio del metodo with y __enter__
09:41:36 PM:ERROR [conexion.py:30] Ocurrió un error de la gran flauta: connection to server at "127.0.0.1", port 3306 failed: received invalid response to SSL negotiation: J

09:44:30 PM:DEBUG [cursor_del_pool.py:10] Inicio del metodo with y __enter__
09:44:30 PM:DEBUG [conexion.py:26] Conexión Exitosa: <connection object at 0x000001F90B4E6CE0; dsn: 'user=postgres password=xxx dbname=test_bd host=localhost port=5432', closed: 0>
09:44:30 PM:DEBUG [usuario_dao.py:20] Seleccionando usuarios
09:44:30 PM:DEBUG [cursor_del_pool.py:16] Se ejecuta el método exit
09:44:30 PM:DEBUG [cursor_del_pool.py:19] Ocurrio una excepcion: relation "usuario" does not exist
LINE 1: SELECT * FROM usuario ORDER BY id_usuario
                      ^

09:48:16 PM:DEBUG [cursor_del_pool.py:11] Inicio del metodo with y __enter__
09:48:16 PM:DEBUG [conexion.py:26] Conexión Exitosa: <connection object at 0x00000250B39AACE0; dsn: 'user=postgres password=xxx dbname=test_bd host=localhost port=5432', closed: 0>
09:48:16 PM:DEBUG [usuario_dao.py:20] Seleccionando usuarios
09:48:16 PM:DEBUG [cursor_del_pool.py:17] Se ejecuta el método exit
09:48:16 PM:DEBUG [cursor_del_pool.py:20] Ocurrio una excepcion: relation "usuario" does not exist
LINE 1: SELECT * FROM usuario ORDER BY id_usuario
                      ^

09:49:25 PM:DEBUG [cursor_del_pool.py:11] Inicio del metodo with y __enter__
09:49:25 PM:DEBUG [conexion.py:26] Conexión Exitosa: <connection object at 0x0000025ED0D06CE0; dsn: 'user=postgres password=xxx dbname=test_bd host=localhost port=5432', closed: 0>
09:49:25 PM:DEBUG [usuario_dao.py:20] Seleccionando usuarios
09:49:25 PM:DEBUG [cursor_del_pool.py:17] Se ejecuta el método exit
09:49:25 PM:DEBUG [cursor_del_pool.py:23] Commit de la transaccion
